{"created": 1614939282.642563, "name": "asyncio", "levelname": "ERROR", "processName": "MainProcess", "threadName": "MainThread", "message": "Task exception was never retrieved\nfuture: <Task finished name='Task-11' coro=<_AsyncioNATSClient.wrap_callback.<locals>.wrapped_callback.<locals>.callback.<locals>.coro_callback_with_reply() done, defined at D:\\work\\OpReturn\\Investigation\\panini-pypi\\venv\\lib\\site-packages\\panini\\nats_client\\_asyncio_cli.py:130> exception=TypeError('Object of type dict_values is not JSON serializable')>", "extra": null, "exc_info": "Traceback (most recent call last):\n  File \"D:\\work\\OpReturn\\Investigation\\panini-pypi\\venv\\lib\\site-packages\\panini\\nats_client\\_asyncio_cli.py\", line 137, in coro_callback_with_reply\n    reply = json.dumps(reply)\n  File \"C:\\Users\\Asus\\AppData\\Local\\Programs\\Python\\Python39\\lib\\json\\__init__.py\", line 231, in dumps\n    return _default_encoder.encode(obj)\n  File \"C:\\Users\\Asus\\AppData\\Local\\Programs\\Python\\Python39\\lib\\json\\encoder.py\", line 199, in encode\n    chunks = self.iterencode(o, _one_shot=True)\n  File \"C:\\Users\\Asus\\AppData\\Local\\Programs\\Python\\Python39\\lib\\json\\encoder.py\", line 257, in iterencode\n    return _iterencode(o, 0)\n  File \"C:\\Users\\Asus\\AppData\\Local\\Programs\\Python\\Python39\\lib\\json\\encoder.py\", line 179, in default\n    raise TypeError(f'Object of type {o.__class__.__name__} '\nTypeError: Object of type dict_values is not JSON serializable"}
{"created": 1614939503.959606, "name": "asyncio", "levelname": "ERROR", "processName": "MainProcess", "threadName": "MainThread", "message": "Task exception was never retrieved\nfuture: <Task finished name='Task-12' coro=<_AsyncioNATSClient.wrap_callback.<locals>.wrapped_callback.<locals>.callback.<locals>.coro_callback_with_reply() done, defined at D:\\work\\OpReturn\\Investigation\\panini-pypi\\venv\\lib\\site-packages\\panini\\nats_client\\_asyncio_cli.py:130> exception=TypeError('Object of type dict_values is not JSON serializable')>", "extra": null, "exc_info": "Traceback (most recent call last):\n  File \"D:\\work\\OpReturn\\Investigation\\panini-pypi\\venv\\lib\\site-packages\\panini\\nats_client\\_asyncio_cli.py\", line 137, in coro_callback_with_reply\n    reply = json.dumps(reply)\n  File \"C:\\Users\\Asus\\AppData\\Local\\Programs\\Python\\Python39\\lib\\json\\__init__.py\", line 231, in dumps\n    return _default_encoder.encode(obj)\n  File \"C:\\Users\\Asus\\AppData\\Local\\Programs\\Python\\Python39\\lib\\json\\encoder.py\", line 199, in encode\n    chunks = self.iterencode(o, _one_shot=True)\n  File \"C:\\Users\\Asus\\AppData\\Local\\Programs\\Python\\Python39\\lib\\json\\encoder.py\", line 257, in iterencode\n    return _iterencode(o, 0)\n  File \"C:\\Users\\Asus\\AppData\\Local\\Programs\\Python\\Python39\\lib\\json\\encoder.py\", line 179, in default\n    raise TypeError(f'Object of type {o.__class__.__name__} '\nTypeError: Object of type dict_values is not JSON serializable"}
{"created": 1614939525.879787, "name": "asyncio", "levelname": "ERROR", "processName": "MainProcess", "threadName": "MainThread", "message": "Task exception was never retrieved\nfuture: <Task finished name='Task-13' coro=<_AsyncioNATSClient.wrap_callback.<locals>.wrapped_callback.<locals>.callback.<locals>.coro_callback_with_reply() done, defined at D:\\work\\OpReturn\\Investigation\\panini-pypi\\venv\\lib\\site-packages\\panini\\nats_client\\_asyncio_cli.py:130> exception=TypeError('Object of type dict_values is not JSON serializable')>", "extra": null, "exc_info": "Traceback (most recent call last):\n  File \"D:\\work\\OpReturn\\Investigation\\panini-pypi\\venv\\lib\\site-packages\\panini\\nats_client\\_asyncio_cli.py\", line 137, in coro_callback_with_reply\n    reply = json.dumps(reply)\n  File \"C:\\Users\\Asus\\AppData\\Local\\Programs\\Python\\Python39\\lib\\json\\__init__.py\", line 231, in dumps\n    return _default_encoder.encode(obj)\n  File \"C:\\Users\\Asus\\AppData\\Local\\Programs\\Python\\Python39\\lib\\json\\encoder.py\", line 199, in encode\n    chunks = self.iterencode(o, _one_shot=True)\n  File \"C:\\Users\\Asus\\AppData\\Local\\Programs\\Python\\Python39\\lib\\json\\encoder.py\", line 257, in iterencode\n    return _iterencode(o, 0)\n  File \"C:\\Users\\Asus\\AppData\\Local\\Programs\\Python\\Python39\\lib\\json\\encoder.py\", line 179, in default\n    raise TypeError(f'Object of type {o.__class__.__name__} '\nTypeError: Object of type dict_values is not JSON serializable"}
{"created": 1614939530.8731637, "name": "asyncio", "levelname": "ERROR", "processName": "MainProcess", "threadName": "MainThread", "message": "Task exception was never retrieved\nfuture: <Task finished name='Task-14' coro=<_AsyncioNATSClient.wrap_callback.<locals>.wrapped_callback.<locals>.callback.<locals>.coro_callback_with_reply() done, defined at D:\\work\\OpReturn\\Investigation\\panini-pypi\\venv\\lib\\site-packages\\panini\\nats_client\\_asyncio_cli.py:130> exception=TypeError('Object of type dict_values is not JSON serializable')>", "extra": null, "exc_info": "Traceback (most recent call last):\n  File \"D:\\work\\OpReturn\\Investigation\\panini-pypi\\venv\\lib\\site-packages\\panini\\nats_client\\_asyncio_cli.py\", line 137, in coro_callback_with_reply\n    reply = json.dumps(reply)\n  File \"C:\\Users\\Asus\\AppData\\Local\\Programs\\Python\\Python39\\lib\\json\\__init__.py\", line 231, in dumps\n    return _default_encoder.encode(obj)\n  File \"C:\\Users\\Asus\\AppData\\Local\\Programs\\Python\\Python39\\lib\\json\\encoder.py\", line 199, in encode\n    chunks = self.iterencode(o, _one_shot=True)\n  File \"C:\\Users\\Asus\\AppData\\Local\\Programs\\Python\\Python39\\lib\\json\\encoder.py\", line 257, in iterencode\n    return _iterencode(o, 0)\n  File \"C:\\Users\\Asus\\AppData\\Local\\Programs\\Python\\Python39\\lib\\json\\encoder.py\", line 179, in default\n    raise TypeError(f'Object of type {o.__class__.__name__} '\nTypeError: Object of type dict_values is not JSON serializable"}
{"created": 1614939543.5404346, "name": "asyncio", "levelname": "ERROR", "processName": "MainProcess", "threadName": "MainThread", "message": "Task exception was never retrieved\nfuture: <Task finished name='Task-15' coro=<_AsyncioNATSClient.wrap_callback.<locals>.wrapped_callback.<locals>.callback.<locals>.coro_callback_with_reply() done, defined at D:\\work\\OpReturn\\Investigation\\panini-pypi\\venv\\lib\\site-packages\\panini\\nats_client\\_asyncio_cli.py:130> exception=TypeError('Object of type dict_values is not JSON serializable')>", "extra": null, "exc_info": "Traceback (most recent call last):\n  File \"D:\\work\\OpReturn\\Investigation\\panini-pypi\\venv\\lib\\site-packages\\panini\\nats_client\\_asyncio_cli.py\", line 137, in coro_callback_with_reply\n    reply = json.dumps(reply)\n  File \"C:\\Users\\Asus\\AppData\\Local\\Programs\\Python\\Python39\\lib\\json\\__init__.py\", line 231, in dumps\n    return _default_encoder.encode(obj)\n  File \"C:\\Users\\Asus\\AppData\\Local\\Programs\\Python\\Python39\\lib\\json\\encoder.py\", line 199, in encode\n    chunks = self.iterencode(o, _one_shot=True)\n  File \"C:\\Users\\Asus\\AppData\\Local\\Programs\\Python\\Python39\\lib\\json\\encoder.py\", line 257, in iterencode\n    return _iterencode(o, 0)\n  File \"C:\\Users\\Asus\\AppData\\Local\\Programs\\Python\\Python39\\lib\\json\\encoder.py\", line 179, in default\n    raise TypeError(f'Object of type {o.__class__.__name__} '\nTypeError: Object of type dict_values is not JSON serializable"}
{"created": 1614940515.0296094, "name": "asyncio", "levelname": "ERROR", "processName": "MainProcess", "threadName": "MainThread", "message": "Task exception was never retrieved\nfuture: <Task finished name='Task-11' coro=<_AsyncioNATSClient.wrap_callback.<locals>.wrapped_callback.<locals>.callback.<locals>.coro_callback_with_reply() done, defined at D:\\work\\OpReturn\\Investigation\\panini-pypi\\venv\\lib\\site-packages\\panini\\nats_client\\_asyncio_cli.py:130> exception=TypeError('Object of type Task is not JSON serializable')>", "extra": null, "exc_info": "Traceback (most recent call last):\n  File \"D:\\work\\OpReturn\\Investigation\\panini-pypi\\venv\\lib\\site-packages\\panini\\nats_client\\_asyncio_cli.py\", line 137, in coro_callback_with_reply\n    reply = json.dumps(reply)\n  File \"C:\\Users\\Asus\\AppData\\Local\\Programs\\Python\\Python39\\lib\\json\\__init__.py\", line 231, in dumps\n    return _default_encoder.encode(obj)\n  File \"C:\\Users\\Asus\\AppData\\Local\\Programs\\Python\\Python39\\lib\\json\\encoder.py\", line 199, in encode\n    chunks = self.iterencode(o, _one_shot=True)\n  File \"C:\\Users\\Asus\\AppData\\Local\\Programs\\Python\\Python39\\lib\\json\\encoder.py\", line 257, in iterencode\n    return _iterencode(o, 0)\n  File \"C:\\Users\\Asus\\AppData\\Local\\Programs\\Python\\Python39\\lib\\json\\encoder.py\", line 179, in default\n    raise TypeError(f'Object of type {o.__class__.__name__} '\nTypeError: Object of type Task is not JSON serializable"}
{"created": 1614940720.2490752, "name": "asyncio", "levelname": "ERROR", "processName": "MainProcess", "threadName": "MainThread", "message": "Task exception was never retrieved\nfuture: <Task finished name='Task-11' coro=<_AsyncioNATSClient.wrap_callback.<locals>.wrapped_callback.<locals>.callback.<locals>.coro_callback_with_reply() done, defined at D:\\work\\OpReturn\\Investigation\\panini-pypi\\venv\\lib\\site-packages\\panini\\nats_client\\_asyncio_cli.py:130> exception=TypeError('Object of type Task is not JSON serializable')>", "extra": null, "exc_info": "Traceback (most recent call last):\n  File \"D:\\work\\OpReturn\\Investigation\\panini-pypi\\venv\\lib\\site-packages\\panini\\nats_client\\_asyncio_cli.py\", line 137, in coro_callback_with_reply\n    reply = json.dumps(reply)\n  File \"C:\\Users\\Asus\\AppData\\Local\\Programs\\Python\\Python39\\lib\\json\\__init__.py\", line 231, in dumps\n    return _default_encoder.encode(obj)\n  File \"C:\\Users\\Asus\\AppData\\Local\\Programs\\Python\\Python39\\lib\\json\\encoder.py\", line 199, in encode\n    chunks = self.iterencode(o, _one_shot=True)\n  File \"C:\\Users\\Asus\\AppData\\Local\\Programs\\Python\\Python39\\lib\\json\\encoder.py\", line 257, in iterencode\n    return _iterencode(o, 0)\n  File \"C:\\Users\\Asus\\AppData\\Local\\Programs\\Python\\Python39\\lib\\json\\encoder.py\", line 179, in default\n    raise TypeError(f'Object of type {o.__class__.__name__} '\nTypeError: Object of type Task is not JSON serializable"}
